Workbook
Name B: MMULT(XtXinv,MMULT(TRANSPOSE(MatX),Y))
Name Errors: Y-Yhat
Name GX: OFFSET(Results!$B$22:$L$22,0,0,1,k+1)
Name k: COLUMNS(X)
Name MatX: OFFSET(X,0,-1,n,k+1)
Name MSE: Results!$E$15
Name n: ROWS(X)
Name Q: OFFSET(Residuals!$C$4,0,0,n,1)
Name s: Results!$J$14
Name S2B: MSE*XtXinv
Name X: OFFSET(Data!$D$5,0,0,COUNT(Data!$D$5:$D$204),COUNT(Data!$D$5:$M$5))
Name X_Axis: Residuals!$P$1:$P$200
Name XR: OFFSET(X,0,0,n,'Partial F'!$D$3-'Partial F'!$D$4)
Name XtXinv: MINVERSE(MMULT(TRANSPOSE(MatX),MatX))
Name Y: OFFSET(Data!$B$5,0,0,COUNT(Data!$B$5:$B$204),1)
Name Yhat: MMULT(MatX,B)
Name Z: OFFSET(Residuals!$D$4,0,0,n,1)

Sheet Data
A1: Multiple Regression | F1: Exports | U1: R^2 | V1: =IF(V2<=k,INDEX(LINEST(OFFSET(V5,0,0,n,1),OFFSET(W5,0,0,n,k-1),1,1),3,1),"") -> 0.52253957 | W1: =IF(W2<=k,INDEX(LINEST(OFFSET(W5,0,0,n,1),OFFSET(X5,0,0,n,k-1),1,1),3,1),"") -> 0.031682568 | X1: =IF(X2<=k,INDEX(LINEST(OFFSET(X5,0,0,n,1),OFFSET(Y5,0,0,n,k-1),1,1),3,1),"") -> 0.5633589 | Y1: =IF(Y2<=k,INDEX(LINEST(OFFSET(Y5,0,0,n,1),OFFSET(Z5,0,0,n,k-1),1,1),3,1),"") -> 0.12691772 | Z1: =IF(Z2<=k,INDEX(LINEST(OFFSET(Z5,0,0,n,1),OFFSET(AA5,0,0,n,k-1),1,1),3,1),"") -> 0.049241455 | AA1: =IF(AA2<=k,INDEX(LINEST(OFFSET(AA5,0,0,n,1),OFFSET(AB5,0,0,n,k-1),1,1),3,1),"") -> 0.023177973 | AB1: =IF(AB2<=k,INDEX(LINEST(OFFSET(AB5,0,0,n,1),OFFSET(AC5,0,0,n,k-1),1,1),3,1),"") | AC1: =IF(AC2<=k,INDEX(LINEST(OFFSET(AC5,0,0,n,1),OFFSET(AD5,0,0,n,k-1),1,1),3,1),"") | ... AM1: =IF(AM2<=k,INDEX(LINEST(OFFSET(AM5,0,0,n,1),OFFSET(AN5,0,0,n,k-1),1,1),3,1),"") | AN1: =IF(AN2<=k,INDEX(LINEST(OFFSET(AN5,0,0,n,1),OFFSET(#REF!,0,0,n,k-1),1,1),3,1),"")
V2: 1 | W2: 2 | X2: 3 | Y2: 4 | Z2: 5 | AA2: 6 | AB2: 7 | AC2: 8 | AD2: 9 | AE2: 10 | AF2: 11 | AG2: 12 | AH2: 13 | AI2: 14 | AJ2: 15 | AK2: 16 | AL2: 17 | AM2: 18 | AN2: 19
B3: Y | C3: 1 | D3: X1 | E3: X2 | F3: X3 | G3: X4 | H3: X5 | I3: X6 | J3: X7 | K3: X8 | L3: X9 | M3: X10 | V3: 1 | W3: =IF(W2<=k,W2,IF(W2<2*k,W2-k,"")) -> 2 | X3: =IF(X2<=k,X2,IF(X2<2*k,X2-k,"")) -> 3 | Y3: =IF(Y2<=k,Y2,IF(Y2<2*k,Y2-k,"")) -> 4 | Z3: =IF(Z2<=k,Z2,IF(Z2<2*k,Z2-k,"")) -> 5 | AA3: =IF(AA2<=k,AA2,IF(AA2<2*k,AA2-k,"")) -> 6 | AB3: =IF(AB2<=k,AB2,IF(AB2<2*k,AB2-k,"")) -> 1 | AC3: =IF(AC2<=k,AC2,IF(AC2<2*k,AC2-k,"")) -> 2 | AD3: =IF(AD2<=k,AD2,IF(AD2<2*k,AD2-k,"")) -> 3 | ... AN3: =IF(AN2<=k,AN2,IF(AN2<2*k,AN2-k,""))
A4: Sl.No. | B4: Price | C4: Ones | D4: Age_08_04 | E4: Mfg_Month | F4: KM | G4: HP | H4: Met_Color | I4: Automatic | V4: {=IF(V3<>"",OFFSET($C$4,0,V3,n+1,k),"")} -> Age_08_04 | W4: {=IF(W3<>"",OFFSET($C$4,0,W3,n+1,k),"")} -> Mfg_Month | X4: {=IF(X3<>"",OFFSET($C$4,0,X3,n+1,k),"")} -> KM | Y4: {=IF(Y3<>"",OFFSET($C$4,0,Y3,n+1,k),"")} -> HP | Z4: {=IF(Z3<>"",OFFSET($C$4,0,Z3,n+1,k),"")} -> Met_Color | AA4: {=IF(AA3<>"",OFFSET($C$4,0,AA3,n+1,k),"")} -> Automatic | AB4: {=IF(AB3<>"",OFFSET($C$4,0,AB3,n+1,k),"")} -> Age_08_04 | AC4: {=IF(AC3<>"",OFFSET($C$4,0,AC3,n+1,k),"")} -> Mfg_Month | ... AN4: {=IF(AN3<>"",OFFSET($C$4,0,AN3,n+1,k),"")}
A5: 1 | B5: 13500 | C5: =IF(B5<>"",1,"") -> 1 | D5: 23 | E5: 10 | F5: 46986 | G5: 90 | H5: 1 | I5: 0 | V5: 23 | W5: 10 | X5: 46986 | Y5: 90 | Z5: 1 | AA5: 0 | AB5: 23 | AC5: 10 | AD5: 46986 | AE5: 90 | AF5: 1
A6: =IF(B6<>"",1+A5,"") -> 2 | B6: 13750 | C6: =IF(B6<>"",1,"") -> 1 | D6: 23 | E6: 10 | F6: 72937 | G6: 90 | H6: 1 | I6: 0 | V6: 23 | W6: 10 | X6: 72937 | Y6: 90 | Z6: 1 | AA6: 0 | AB6: 23 | AC6: 10 | AD6: 72937 | AE6: 90 | AF6: 1
A7: =IF(B7<>"",1+A6,"") -> 3 | B7: 13950 | C7: =IF(B7<>"",1,"") -> 1 | D7: 24 | E7: 9 | F7: 41711 | G7: 90 | H7: 1 | I7: 0 | V7: 24 | W7: 9 | X7: 41711 | Y7: 90 | Z7: 1 | AA7: 0 | AB7: 24 | AC7: 9 | AD7: 41711 | AE7: 90 | AF7: 1
A8: =IF(B8<>"",1+A7,"") -> 4 | B8: 14950 | C8: =IF(B8<>"",1,"") -> 1 | D8: 26 | E8: 7 | F8: 48000 | G8: 90 | H8: 0 | I8: 0 | V8: 26 | W8: 7 | X8: 48000 | Y8: 90 | Z8: 0 | AA8: 0 | AB8: 26 | AC8: 7 | AD8: 48000 | AE8: 90 | AF8: 0
A9: =IF(B9<>"",1+A8,"") -> 5 | B9: 13750 | C9: =IF(B9<>"",1,"") -> 1 | D9: 30 | E9: 3 | F9: 38500 | G9: 90 | H9: 0 | I9: 0 | V9: 30 | W9: 3 | X9: 38500 | Y9: 90 | Z9: 0 | AA9: 0 | AB9: 30 | AC9: 3 | AD9: 38500 | AE9: 90 | AF9: 0
A10: =IF(B10<>"",1+A9,"") -> 6 | B10: 12950 | C10: =IF(B10<>"",1,"") -> 1 | D10: 32 | E10: 1 | F10: 61000 | G10: 90 | H10: 0 | I10: 0 | V10: 32 | W10: 1 | X10: 61000 | Y10: 90 | Z10: 0 | AA10: 0 | AB10: 32 | AC10: 1 | AD10: 61000 | AE10: 90 | AF10: 0
A11: =IF(B11<>"",1+A10,"") -> 7 | B11: 16900 | C11: =IF(B11<>"",1,"") -> 1 | D11: 27 | E11: 6 | F11: 94612 | G11: 90 | H11: 1 | I11: 0 | V11: 27 | W11: 6 | X11: 94612 | Y11: 90 | Z11: 1 | AA11: 0 | AB11: 27 | AC11: 6 | AD11: 94612 | AE11: 90 | AF11: 1
A12: =IF(B12<>"",1+A11,"") -> 8 | B12: 18600 | C12: =IF(B12<>"",1,"") -> 1 | D12: 30 | E12: 3 | F12: 75889 | G12: 90 | H12: 1 | I12: 0 | V12: 30 | W12: 3 | X12: 75889 | Y12: 90 | Z12: 1 | AA12: 0 | AB12: 30 | AC12: 3 | AD12: 75889 | AE12: 90 | AF12: 1
A13: =IF(B13<>"",1+A12,"") -> 9 | B13: 21500 | C13: =IF(B13<>"",1,"") -> 1 | D13: 27 | E13: 6 | F13: 19700 | G13: 192 | H13: 0 | I13: 0 | V13: 27 | W13: 6 | X13: 19700 | Y13: 192 | Z13: 0 | AA13: 0 | AB13: 27 | AC13: 6 | AD13: 19700 | AE13: 192 | AF13: 0
A14: =IF(B14<>"",1+A13,"") -> 10 | B14: 12950 | C14: =IF(B14<>"",1,"") -> 1 | D14: 23 | E14: 10 | F14: 71138 | G14: 69 | H14: 0 | I14: 0 | V14: 23 | W14: 10 | X14: 71138 | Y14: 69 | Z14: 0 | AA14: 0 | AB14: 23 | AC14: 10 | AD14: 71138 | AE14: 69 | AF14: 0
A15: =IF(B15<>"",1+A14,"") -> 11 | B15: 20950 | C15: =IF(B15<>"",1,"") -> 1 | D15: 25 | E15: 8 | F15: 31461 | G15: 192 | H15: 0 | I15: 0 | V15: 25 | W15: 8 | X15: 31461 | Y15: 192 | Z15: 0 | AA15: 0 | AB15: 25 | AC15: 8 | AD15: 31461 | AE15: 192 | AF15: 0
A16: =IF(B16<>"",1+A15,"") -> 12 | B16: 19950 | C16: =IF(B16<>"",1,"") -> 1 | D16: 22 | E16: 11 | F16: 43610 | G16: 192 | H16: 0 | I16: 0 | V16: 22 | W16: 11 | X16: 43610 | Y16: 192 | Z16: 0 | AA16: 0 | AB16: 22 | AC16: 11 | AD16: 43610 | AE16: 192 | AF16: 0
A17: =IF(B17<>"",1+A16,"") -> 13 | B17: 19600 | C17: =IF(B17<>"",1,"") -> 1 | D17: 25 | E17: 8 | F17: 32189 | G17: 192 | H17: 0 | I17: 0 | V17: 25 | W17: 8 | X17: 32189 | Y17: 192 | Z17: 0 | AA17: 0 | AB17: 25 | AC17: 8 | AD17: 32189 | AE17: 192 | AF17: 0
... A203: =IF(B203<>"",1+A202,"") -> 199 | B203: 9950 | C203: =IF(B203<>"",1,"") -> 1 | D203: 42 | E203: 3 | F203: 105699 | G203: 97 | H203: 1 | I203: 0 | V203: 42 | W203: 3 | X203: 105699 | Y203: 97 | Z203: 1 | AA203: 0 | AB203: 42 | AC203: 3 | AD203: 105699 | AE203: 97 | AF203: 1
A204: =IF(B204<>"",1+A203,"") | C204: =IF(B204<>"",1,"") | V204: #N/A | W204: #N/A | X204: #N/A | Y204: #N/A | Z204: #N/A | AA204: #N/A | AB204: #N/A | AC204: #N/A | AD204: #N/A | AE204: #N/A | AF204: #N/A

Sheet Results
A1: Multiple Regression Results | F1: =Data!F1 -> Exports
B3: 0 | C3: 1 | D3: 2 | E3: 3 | F3: 4 | G3: 5 | H3: 6 | I3: 7 | J3: 8 | K3: 9 | L3: 10
B4: Intercept | C4: =IF(Data!D4<>"",Data!D4,"") -> Age_08_04 | D4: =IF(Data!E4<>"",Data!E4,"") -> Mfg_Month | E4: =IF(Data!F4<>"",Data!F4,"") -> KM | F4: =IF(Data!G4<>"",Data!G4,"") -> HP | G4: =IF(Data!H4<>"",Data!H4,"") -> Met_Color | H4: =IF(Data!I4<>"",Data!I4,"") -> Automatic | I4: =IF(Data!J4<>"",Data!J4,"") | J4: =IF(Data!K4<>"",Data!K4,"") | ... L4: =IF(Data!M4<>"",Data!M4,"")
A5: b | B5: =IF(ISERROR(INDEX(B,B3+1)),"",INDEX(B,B3+1)) -> 16157.241 | C5: =IF(ISERROR(INDEX(B,C3+1)),"",INDEX(B,C3+1)) -> -233.17932 | D5: =IF(ISERROR(INDEX(B,D3+1)),"",INDEX(B,D3+1)) -> -130.57976 | E5: =IF(ISERROR(INDEX(B,E3+1)),"",INDEX(B,E3+1)) -> -0.0083666765 | F5: =IF(ISERROR(INDEX(B,F3+1)),"",INDEX(B,F3+1)) -> 66.805142 | G5: =IF(ISERROR(INDEX(B,G3+1)),"",INDEX(B,G3+1)) -> 512.59129 | H5: =IF(ISERROR(INDEX(B,H3+1)),"",INDEX(B,H3+1)) -> 1298.7918 | I5: =IF(ISERROR(INDEX(B,I3+1)),"",INDEX(B,I3+1)) | ... L5: =IF(ISERROR(INDEX(B,L3+1)),"",INDEX(B,L3+1)) | N5: Press the F9 key before reading these results.
A6: s(b) | B6: =IF(ISERROR(INDEX(S2B,B3+1,B3+1)),"",SQRT(INDEX(S2B,B3+1,B3+1))) -> 1002.2659 | C6: =IF(ISERROR(INDEX(S2B,C3+1,C3+1)),"",SQRT(INDEX(S2B,C3+1,C3+1))) -> 24.801243 | D6: =IF(ISERROR(INDEX(S2B,D3+1,D3+1)),"",SQRT(INDEX(S2B,D3+1,D3+1))) -> 48.659935 | E6: =IF(ISERROR(INDEX(S2B,E3+1,E3+1)),"",SQRT(INDEX(S2B,E3+1,E3+1))) -> 0.0064994367 | F6: =IF(ISERROR(INDEX(S2B,F3+1,F3+1)),"",SQRT(INDEX(S2B,F3+1,F3+1))) -> 7.3370195 | G6: =IF(ISERROR(INDEX(S2B,G3+1,G3+1)),"",SQRT(INDEX(S2B,G3+1,G3+1))) -> 380.4563 | H6: =IF(ISERROR(INDEX(S2B,H3+1,H3+1)),"",SQRT(INDEX(S2B,H3+1,H3+1))) -> 702.69361 | I6: =IF(ISERROR(INDEX(S2B,I3+1,I3+1)),"",SQRT(INDEX(S2B,I3+1,I3+1))) | ... L6: =IF(ISERROR(INDEX(S2B,L3+1,L3+1)),"",SQRT(INDEX(S2B,L3+1,L3+1)))
A7: t | B7: =IF(B5<>"",B5/B6,"") -> 16.120712 | C7: =IF(C5<>"",C5/C6,"") -> -9.4019207 | D7: =IF(D5<>"",D5/D6,"") -> -2.683517 | E7: =IF(E5<>"",E5/E6,"") -> -1.2872926 | F7: =IF(F5<>"",F5/F6,"") -> 9.1052152 | G7: =IF(G5<>"",G5/G6,"") -> 1.3473066 | H7: =IF(H5<>"",H5/H6,"") -> 1.8483045 | I7: =IF(I5<>"",I5/I6,"") | ... L7: =IF(L5<>"",L5/L6,"")
A8: p-value | B8: =IF(B7<>"",TDIST(ABS(B7),$D$15,2),"") -> 1.5601001e-37 | C8: =IF(C7<>"",TDIST(ABS(C7),$D$15,2),"") -> 1.6461356e-17 | D8: =IF(D7<>"",TDIST(ABS(D7),$D$15,2),"") -> 0.0079213455 | E8: =IF(E7<>"",TDIST(ABS(E7),$D$15,2),"") -> 0.19954197 | F8: =IF(F7<>"",TDIST(ABS(F7),$D$15,2),"") -> 1.1229965e-16 | G8: =IF(G7<>"",TDIST(ABS(G7),$D$15,2),"") -> 0.17946935 | H8: =IF(H7<>"",TDIST(ABS(H7),$D$15,2),"") -> 0.066096269 | I8: =IF(I7<>"",TDIST(ABS(I7),$D$15,2),"") | ... L8: =IF(L7<>"",TDIST(ABS(L7),$D$15,2),"")
B10: VIF | C10: =IF(C3<=k,1/(1-Data!V1),"") -> 2.0944144 | D10: =IF(D3<=k,1/(1-Data!W1),"") -> 1.0327192 | E10: =IF(E3<=k,1/(1-Data!X1),"") -> 2.2902104 | F10: =IF(F3<=k,1/(1-Data!Y1),"") -> 1.1453674 | G10: =IF(G3<=k,1/(1-Data!Z1),"") -> 1.0517918 | H10: =IF(H3<=k,1/(1-Data!AA1),"") -> 1.0237279 | I10: =IF(I3<=k,1/(1-Data!AB1),"") | J10: =IF(J3<=k,1/(1-Data!AC1),"") | ... L10: =IF(L3<=k,1/(1-Data!AE1),"")
A12: ANOVA Table
B13: Source | C13: SS | D13: df | E13: MS | F13: F | G13: FCritical | H13: p-value
B14: Regn. | C14: =DEVSQ(Yhat) -> 1.7792496e+09 | D14: =k -> 6 | E14: =C14/D14 -> 2.9654161e+08 | F14: =E14/E15 -> 59.161712 | G14: =FINV(5%,D14,D15) -> 2.1460499 | H14: =FDIST(F14,D14,D15) -> 4.5568848e-41 | I14: s | J14: =SQRT(MSE) -> 2238.8369
B15: Error | C15: =SUMSQ(Errors) -> 9.6237899e+08 | D15: =n-k-1 -> 192 | E15: =C15/D15 -> 5012390.6
B16: Total | C16: =DEVSQ(Y) -> 2.7416286e+09 | D16: =n-1 -> 198 | E16: =C16/D16 -> 13846609 | F16: R2 | G16: =C14/C16 -> 0.64897544 | I16: Adjusted R2 | J16: =1-E15/E16 -> 0.63800592
A19: Prediction Interval
A21: Given X | C21: =C4 -> Age_08_04 | D21: =D4 -> Mfg_Month | E21: =E4 -> KM | F21: =F4 -> HP | G21: =G4 -> Met_Color | H21: =H4 -> Automatic | I21: =I4 | J21: =J4 | ... L21: =L4
B22: 1 | C22: 5 | D22: 10 | E22: 150 | F22: 2
B24: 1-a | C24: (1-a) CI for Y for given X | G24: 1-a | H24: (1-a) CI for E[Y | X]
B25: 0.95 | C25: =IF(COUNT(GX)<>k+1,"",MMULT(GX,B)) | D25: + or - | E25: {=IF(C25<>"",TINV(1-B25,D15)*SQRT(E15)*SQRT(1+MMULT(MMULT(GX,XtXinv),TRANSPOSE(GX))),"")} | G25: 0.95 | H25: =C25 | I25: + or - | J25: {=IF(C25<>"",TINV(1-G25,$D$15)*SQRT($E$15)*SQRT(MMULT(MMULT(GX,XtXinv),TRANSPOSE(GX))),"")}
B28: Press the F9 key before reading the results.

Sheet Residuals
A1: Residual Analysis | H1: =Data!F1 -> Exports | N1: =Data!B4 -> Price | O1: 1 | P1: {=IF(O1=1,Y,OFFSET(MatX,0,O1-1,n,1))} -> 13500 | T1: =3*s -> 6716.5107 | U1: 3
N2: {=IF(TRANSPOSE(Data!D4:M4)=0,"",TRANSPOSE(Data!D4:M4))} -> Age_08_04 | P2: 13750 | T2: =-T1 -> -6716.5107 | U2: -3
B3: Errors | C3: Q | D3: Z | N3: Mfg_Month | P3: 13950
B4: {=IF(ROW(B1:B200)>n,"",Errors)} -> -2120.2563 | C4: {=IF(ISNUMBER(B4),(SUM(IF(B4>Errors,1,0))+1+(SUM(IF(B4=Errors,1,0))-1)/2)/(n+1),"")} -> 0.125 | D4: =IF(C4<>"",NORMSINV(C4),"") -> -1.1503494 | G4: Durbin-Watson d = | H4: {=SUMSQ(OFFSET(B4:B103,0,0,n-1)-OFFSET(B4:B103,1,0,n-1))/SUMSQ(Errors)} -> 1.4754227 | N4: KM | P4: 14950
B5: -1653.1327 | C5: {=IF(ISNUMBER(B5),(SUM(IF(B5>Errors,1,0))+1+(SUM(IF(B5=Errors,1,0))-1)/2)/(n+1),"")} -> 0.21 | D5: =IF(C5<>"",NORMSINV(C5),"") -> -0.80642125 | N5: HP | P5: 13750
B6: -1611.791 | C6: {=IF(ISNUMBER(B6),(SUM(IF(B6>Errors,1,0))+1+(SUM(IF(B6=Errors,1,0))-1)/2)/(n+1),"")} -> 0.22 | D6: =IF(C6<>"",NORMSINV(C6),"") -> -0.77219321 | N6: Met_Color | P6: 12950
B7: 158.61742 | C7: {=IF(ISNUMBER(B7),(SUM(IF(B7>Errors,1,0))+1+(SUM(IF(B7=Errors,1,0))-1)/2)/(n+1),"")} -> 0.575 | D7: =IF(C7<>"",NORMSINV(C7),"") -> 0.18911843 | N7: Automatic | P7: 16900
B8: -710.46779 | C8: {=IF(ISNUMBER(B8),(SUM(IF(B8>Errors,1,0))+1+(SUM(IF(B8=Errors,1,0))-1)/2)/(n+1),"")} -> 0.375 | D8: =IF(C8<>"",NORMSINV(C8),"") -> -0.31863936 | P8: 18600
B9: -1117.0185 | C9: {=IF(ISNUMBER(B9),(SUM(IF(B9>Errors,1,0))+1+(SUM(IF(B9=Errors,1,0))-1)/2)/(n+1),"")} -> 0.315 | D9: =IF(C9<>"",NORMSINV(C9),"") -> -0.48172685 | P9: 21500
B10: 2088.6132 | C10: {=IF(ISNUMBER(B10),(SUM(IF(B10>Errors,1,0))+1+(SUM(IF(B10=Errors,1,0))-1)/2)/(n+1),"")} -> 0.84 | D10: =IF(C10<>"",NORMSINV(C10),"") -> 0.99445788 | P10: 12950
B11: 3939.7626 | C11: {=IF(ISNUMBER(B11),(SUM(IF(B11>Errors,1,0))+1+(SUM(IF(B11=Errors,1,0))-1)/2)/(n+1),"")} -> 0.955 | D11: =IF(C11<>"",NORMSINV(C11),"") -> 1.6953977 | P11: 20950
B12: -239.68441 | C12: {=IF(ISNUMBER(B12),(SUM(IF(B12>Errors,1,0))+1+(SUM(IF(B12=Errors,1,0))-1)/2)/(n+1),"")} -> 0.48 | D12: =IF(C12<>"",NORMSINV(C12),"") -> -0.050153583 | P12: 19950
B13: -552.68511 | C13: {=IF(ISNUMBER(B13),(SUM(IF(B13>Errors,1,0))+1+(SUM(IF(B13=Errors,1,0))-1)/2)/(n+1),"")} -> 0.43 | D13: =IF(C13<>"",NORMSINV(C13),"") -> -0.17637416 | M13: X Axis | P13: 19600
B14: -896.48304 | C14: {=IF(ISNUMBER(B14),(SUM(IF(B14>Errors,1,0))+1+(SUM(IF(B14=Errors,1,0))-1)/2)/(n+1),"")} -> 0.355 | D14: =IF(C14<>"",NORMSINV(C14),"") -> -0.37185609 | P14: 21500 | S14: Select X Axis for the Residual Plot.
B15: -2102.6349 | C15: {=IF(ISNUMBER(B15),(SUM(IF(B15>Errors,1,0))+1+(SUM(IF(B15=Errors,1,0))-1)/2)/(n+1),"")} -> 0.14 | D15: =IF(C15<>"",NORMSINV(C15),"") -> -1.0803193 | P15: 22500 | S15: Press the F9 key.
B16: -2240.3921 | C16: {=IF(ISNUMBER(B16),(SUM(IF(B16>Errors,1,0))+1+(SUM(IF(B16=Errors,1,0))-1)/2)/(n+1),"")} -> 0.1 | D16: =IF(C16<>"",NORMSINV(C16),"") -> -1.2815516 | P16: 22000
B17: -314.26745 | C17: {=IF(ISNUMBER(B17),(SUM(IF(B17>Errors,1,0))+1+(SUM(IF(B17=Errors,1,0))-1)/2)/(n+1),"")} -> 0.46 | D17: =IF(C17<>"",NORMSINV(C17),"") -> -0.10043372 | P17: 22750
B18: 881.46158 | C18: {=IF(ISNUMBER(B18),(SUM(IF(B18>Errors,1,0))+1+(SUM(IF(B18=Errors,1,0))-1)/2)/(n+1),"")} -> 0.745 | D18: =IF(C18<>"",NORMSINV(C18),"") -> 0.65883769 | P18: 17950
B19: 354.87477 | C19: {=IF(ISNUMBER(B19),(SUM(IF(B19>Errors,1,0))+1+(SUM(IF(B19=Errors,1,0))-1)/2)/(n+1),"")} -> 0.615 | D19: =IF(C19<>"",NORMSINV(C19),"") -> 0.2923749 | P19: 16750
B20: 925.16643 | C20: {=IF(ISNUMBER(B20),(SUM(IF(B20>Errors,1,0))+1+(SUM(IF(B20=Errors,1,0))-1)/2)/(n+1),"")} -> 0.755 | D20: =IF(C20<>"",NORMSINV(C20),"") -> 0.69030882 | P20: 16950
B21: 884.81446 | C21: {=IF(ISNUMBER(B21),(SUM(IF(B21>Errors,1,0))+1+(SUM(IF(B21=Errors,1,0))-1)/2)/(n+1),"")} -> 0.75 | D21: =IF(C21<>"",NORMSINV(C21),"") -> 0.67448975 | P21: 15950
B22: 229.59236 | C22: {=IF(ISNUMBER(B22),(SUM(IF(B22>Errors,1,0))+1+(SUM(IF(B22=Errors,1,0))-1)/2)/(n+1),"")} -> 0.595 | D22: =IF(C22<>"",NORMSINV(C22),"") -> 0.24042603 | P22: 16950
B23: 857.19197 | C23: {=IF(ISNUMBER(B23),(SUM(IF(B23>Errors,1,0))+1+(SUM(IF(B23=Errors,1,0))-1)/2)/(n+1),"")} -> 0.735 | D23: =IF(C23<>"",NORMSINV(C23),"") -> 0.62800601 | P23: 15950
B24: -115.18963 | C24: {=IF(ISNUMBER(B24),(SUM(IF(B24>Errors,1,0))+1+(SUM(IF(B24=Errors,1,0))-1)/2)/(n+1),"")} -> 0.505 | D24: =IF(C24<>"",NORMSINV(C24),"") -> 0.01253347 | P24: 16950
B25: -202.74007 | C25: {=IF(ISNUMBER(B25),(SUM(IF(B25>Errors,1,0))+1+(SUM(IF(B25=Errors,1,0))-1)/2)/(n+1),"")} -> 0.485 | D25: =IF(C25<>"",NORMSINV(C25),"") -> -0.037608288 | P25: 16250
B26: -415.02422 | C26: {=IF(ISNUMBER(B26),(SUM(IF(B26>Errors,1,0))+1+(SUM(IF(B26=Errors,1,0))-1)/2)/(n+1),"")} -> 0.455 | D26: =IF(C26<>"",NORMSINV(C26),"") -> -0.11303854 | P26: 15950
B27: 383.09625 | C27: {=IF(ISNUMBER(B27),(SUM(IF(B27>Errors,1,0))+1+(SUM(IF(B27=Errors,1,0))-1)/2)/(n+1),"")} -> 0.62 | D27: =IF(C27<>"",NORMSINV(C27),"") -> 0.30548079 | P27: 17495
... B100: -2262.0912 | C100: {=IF(ISNUMBER(B100),(SUM(IF(B100>Errors,1,0))+1+(SUM(IF(B100=Errors,1,0))-1)/2)/(n+1),"")} -> 0.095 | D100: =IF(C100<>"",NORMSINV(C100),"") -> -1.3105791 | P100: 17450
B101: -2291.2658 | C101: {=IF(ISNUMBER(B101),(SUM(IF(B101>Errors,1,0))+1+(SUM(IF(B101=Errors,1,0))-1)/2)/(n+1),"")} -> 0.09 | D101: =IF(C101<>"",NORMSINV(C101),"") -> -1.340755
B102: -1192.6441 | C102: {=IF(ISNUMBER(B102),(SUM(IF(B102>Errors,1,0))+1+(SUM(IF(B102=Errors,1,0))-1)/2)/(n+1),"")} -> 0.295 | D102: =IF(C102<>"",NORMSINV(C102),"") -> -0.53883603
B103: -910.98362 | C103: {=IF(ISNUMBER(B103),(SUM(IF(B103>Errors,1,0))+1+(SUM(IF(B103=Errors,1,0))-1)/2)/(n+1),"")} -> 0.35 | D103: =IF(C103<>"",NORMSINV(C103),"") -> -0.38532047
B104: -40.333928 | C104: {=IF(ISNUMBER(B104),(SUM(IF(B104>Errors,1,0))+1+(SUM(IF(B104=Errors,1,0))-1)/2)/(n+1),"")} -> 0.525 | D104: =IF(C104<>"",NORMSINV(C104),"") -> 0.062706778
B105: -2047.7242 | C105: {=IF(ISNUMBER(B105),(SUM(IF(B105>Errors,1,0))+1+(SUM(IF(B105=Errors,1,0))-1)/2)/(n+1),"")} -> 0.15 | D105: =IF(C105<>"",NORMSINV(C105),"") -> -1.0364334
B106: 1826.1635 | C106: {=IF(ISNUMBER(B106),(SUM(IF(B106>Errors,1,0))+1+(SUM(IF(B106=Errors,1,0))-1)/2)/(n+1),"")} -> 0.805 | D106: =IF(C106<>"",NORMSINV(C106),"") -> 0.85961736
B107: -1512.7317 | C107: {=IF(ISNUMBER(B107),(SUM(IF(B107>Errors,1,0))+1+(SUM(IF(B107=Errors,1,0))-1)/2)/(n+1),"")} -> 0.24 | D107: =IF(C107<>"",NORMSINV(C107),"") -> -0.70630256
B108: -1873.9731 | C108: {=IF(ISNUMBER(B108),(SUM(IF(B108>Errors,1,0))+1+(SUM(IF(B108=Errors,1,0))-1)/2)/(n+1),"")} -> 0.175 | D108: =IF(C108<>"",NORMSINV(C108),"") -> -0.93458929
B109: -1393.3393 | C109: {=IF(ISNUMBER(B109),(SUM(IF(B109>Errors,1,0))+1+(SUM(IF(B109=Errors,1,0))-1)/2)/(n+1),"")} -> 0.265 | D109: =IF(C109<>"",NORMSINV(C109),"") -> -0.62800601
B110: -943.6122 | C110: {=IF(ISNUMBER(B110),(SUM(IF(B110>Errors,1,0))+1+(SUM(IF(B110=Errors,1,0))-1)/2)/(n+1),"")} -> 0.345 | D110: =IF(C110<>"",NORMSINV(C110),"") -> -0.39885507
B111: -1129.8967 | C111: {=IF(ISNUMBER(B111),(SUM(IF(B111>Errors,1,0))+1+(SUM(IF(B111=Errors,1,0))-1)/2)/(n+1),"")} -> 0.31 | D111: =IF(C111<>"",NORMSINV(C111),"") -> -0.49585035
B112: -1214.1004 | C112: {=IF(ISNUMBER(B112),(SUM(IF(B112>Errors,1,0))+1+(SUM(IF(B112=Errors,1,0))-1)/2)/(n+1),"")} -> 0.285 | D112: =IF(C112<>"",NORMSINV(C112),"") -> -0.5680515
...

Sheet Correl
A1: Correlation matrix | E1: =Data!F1 -> Exports
C3: 1 | D3: 2 | E3: 3 | F3: 4 | G3: 5 | H3: 6 | I3: 7 | J3: 8 | K3: 9 | L3: 10 | N3: Press the F9 key before reading the results.
C4: =IF(Data!D4<>"",Data!D4,"") -> Age_08_04 | D4: =IF(Data!E4<>"",Data!E4,"") -> Mfg_Month | E4: =IF(Data!F4<>"",Data!F4,"") -> KM | F4: =IF(Data!G4<>"",Data!G4,"") -> HP | G4: =IF(Data!H4<>"",Data!H4,"") -> Met_Color | H4: =IF(Data!I4<>"",Data!I4,"") -> Automatic | I4: =IF(Data!J4<>"",Data!J4,"") | J4: =IF(Data!K4<>"",Data!K4,"") | ... L4: =IF(Data!M4<>"",Data!M4,"")
A5: 1 | B5: =C4 -> Age_08_04 | C5: 1
A6: 2 | B6: =D4 -> Mfg_Month | C6: =IF(AND($B6<>"",C$4<>""),CORREL(OFFSET(X,0,$A6-1,n,1),OFFSET(X,0,C$3-1,n,1)),"") -> -0.1238543 | D6: =IF(B6<>"",1,"") -> 1
A7: 3 | B7: =E4 -> KM | C7: =IF(AND($B7<>"",C$4<>""),CORREL(OFFSET(X,0,$A7-1,n,1),OFFSET(X,0,C$3-1,n,1)),"") -> 0.69925173 | D7: =IF(AND($B7<>"",D$4<>""),CORREL(OFFSET(X,0,$A7-1,n,1),OFFSET(X,0,D$3-1,n,1)),"") -> -0.028477981 | E7: =IF($B7<>"",1,"") -> 1
A8: 4 | B8: =F4 -> HP | C8: =IF(AND($B8<>"",C$4<>""),CORREL(OFFSET(X,0,$A8-1,n,1),OFFSET(X,0,C$3-1,n,1)),"") -> -0.059126497 | D8: =IF(AND($B8<>"",D$4<>""),CORREL(OFFSET(X,0,$A8-1,n,1),OFFSET(X,0,D$3-1,n,1)),"") -> -0.0038541061 | E8: =IF(AND($B8<>"",E$4<>""),CORREL(OFFSET(X,0,$A8-1,n,1),OFFSET(X,0,E$3-1,n,1)),"") -> -0.27847774 | F8: =IF($B8<>"",1,"") -> 1
A9: 5 | B9: =G4 -> Met_Color | C9: =IF(AND($B9<>"",C$4<>""),CORREL(OFFSET(X,0,$A9-1,n,1),OFFSET(X,0,C$3-1,n,1)),"") -> -0.11525361 | D9: =IF(AND($B9<>"",D$4<>""),CORREL(OFFSET(X,0,$A9-1,n,1),OFFSET(X,0,D$3-1,n,1)),"") -> -0.040834418 | E9: =IF(AND($B9<>"",E$4<>""),CORREL(OFFSET(X,0,$A9-1,n,1),OFFSET(X,0,E$3-1,n,1)),"") -> -0.16416165 | F9: =IF(AND($B9<>"",F$4<>""),CORREL(OFFSET(X,0,$A9-1,n,1),OFFSET(X,0,F$3-1,n,1)),"") -> -0.067895976 | G9: =IF($B9<>"",1,"") -> 1
A10: 6 | B10: =H4 -> Automatic | C10: =IF(AND($B10<>"",C$4<>""),CORREL(OFFSET(X,0,$A10-1,n,1),OFFSET(X,0,C$3-1,n,1)),"") -> 0.0016108372 | D10: =IF(AND($B10<>"",D$4<>""),CORREL(OFFSET(X,0,$A10-1,n,1),OFFSET(X,0,D$3-1,n,1)),"") -> 0.081514526 | E10: =IF(AND($B10<>"",E$4<>""),CORREL(OFFSET(X,0,$A10-1,n,1),OFFSET(X,0,E$3-1,n,1)),"") -> -0.066730976 | F10: =IF(AND($B10<>"",F$4<>""),CORREL(OFFSET(X,0,$A10-1,n,1),OFFSET(X,0,F$3-1,n,1)),"") -> 0.035442101 | G10: =IF(AND($B10<>"",G$4<>""),CORREL(OFFSET(X,0,$A10-1,n,1),OFFSET(X,0,G$3-1,n,1)),"") -> -0.069223003 | H10: =IF($B10<>"",1,"") -> 1
A11: 7 | B11: =I4 | C11: =IF(AND($B11<>"",C$4<>""),CORREL(OFFSET(X,0,$A11-1,n,1),OFFSET(X,0,C$3-1,n,1)),"") | D11: =IF(AND($B11<>"",D$4<>""),CORREL(OFFSET(X,0,$A11-1,n,1),OFFSET(X,0,D$3-1,n,1)),"") | E11: =IF(AND($B11<>"",E$4<>""),CORREL(OFFSET(X,0,$A11-1,n,1),OFFSET(X,0,E$3-1,n,1)),"") | F11: =IF(AND($B11<>"",F$4<>""),CORREL(OFFSET(X,0,$A11-1,n,1),OFFSET(X,0,F$3-1,n,1)),"") | G11: =IF(AND($B11<>"",G$4<>""),CORREL(OFFSET(X,0,$A11-1,n,1),OFFSET(X,0,G$3-1,n,1)),"") | H11: =IF(AND($B11<>"",H$4<>""),CORREL(OFFSET(X,0,$A11-1,n,1),OFFSET(X,0,H$3-1,n,1)),"") | I11: =IF($B11<>"",1,"")
A12: 8 | B12: =J4 | C12: =IF(AND($B12<>"",C$4<>""),CORREL(OFFSET(X,0,$A12-1,n,1),OFFSET(X,0,C$3-1,n,1)),"") | D12: =IF(AND($B12<>"",D$4<>""),CORREL(OFFSET(X,0,$A12-1,n,1),OFFSET(X,0,D$3-1,n,1)),"") | E12: =IF(AND($B12<>"",E$4<>""),CORREL(OFFSET(X,0,$A12-1,n,1),OFFSET(X,0,E$3-1,n,1)),"") | F12: =IF(AND($B12<>"",F$4<>""),CORREL(OFFSET(X,0,$A12-1,n,1),OFFSET(X,0,F$3-1,n,1)),"") | G12: =IF(AND($B12<>"",G$4<>""),CORREL(OFFSET(X,0,$A12-1,n,1),OFFSET(X,0,G$3-1,n,1)),"") | H12: =IF(AND($B12<>"",H$4<>""),CORREL(OFFSET(X,0,$A12-1,n,1),OFFSET(X,0,H$3-1,n,1)),"") | I12: =IF(AND($B12<>"",I$4<>""),CORREL(OFFSET(X,0,$A12-1,n,1),OFFSET(X,0,I$3-1,n,1)),"") | J12: =IF($B12<>"",1,"")
A13: 9 | B13: =K4 | C13: =IF(AND($B13<>"",C$4<>""),CORREL(OFFSET(X,0,$A13-1,n,1),OFFSET(X,0,C$3-1,n,1)),"") | D13: =IF(AND($B13<>"",D$4<>""),CORREL(OFFSET(X,0,$A13-1,n,1),OFFSET(X,0,D$3-1,n,1)),"") | E13: =IF(AND($B13<>"",E$4<>""),CORREL(OFFSET(X,0,$A13-1,n,1),OFFSET(X,0,E$3-1,n,1)),"") | F13: =IF(AND($B13<>"",F$4<>""),CORREL(OFFSET(X,0,$A13-1,n,1),OFFSET(X,0,F$3-1,n,1)),"") | G13: =IF(AND($B13<>"",G$4<>""),CORREL(OFFSET(X,0,$A13-1,n,1),OFFSET(X,0,G$3-1,n,1)),"") | H13: =IF(AND($B13<>"",H$4<>""),CORREL(OFFSET(X,0,$A13-1,n,1),OFFSET(X,0,H$3-1,n,1)),"") | I13: =IF(AND($B13<>"",I$4<>""),CORREL(OFFSET(X,0,$A13-1,n,1),OFFSET(X,0,I$3-1,n,1)),"") | J13: =IF(AND($B13<>"",J$4<>""),CORREL(OFFSET(X,0,$A13-1,n,1),OFFSET(X,0,J$3-1,n,1)),"") | K13: =IF($B13<>"",1,"")
A14: 10 | B14: =L4 | C14: =IF(AND($B14<>"",C$4<>""),CORREL(OFFSET(X,0,$A14-1,n,1),OFFSET(X,0,C$3-1,n,1)),"") | D14: =IF(AND($B14<>"",D$4<>""),CORREL(OFFSET(X,0,$A14-1,n,1),OFFSET(X,0,D$3-1,n,1)),"") | E14: =IF(AND($B14<>"",E$4<>""),CORREL(OFFSET(X,0,$A14-1,n,1),OFFSET(X,0,E$3-1,n,1)),"") | F14: =IF(AND($B14<>"",F$4<>""),CORREL(OFFSET(X,0,$A14-1,n,1),OFFSET(X,0,F$3-1,n,1)),"") | G14: =IF(AND($B14<>"",G$4<>""),CORREL(OFFSET(X,0,$A14-1,n,1),OFFSET(X,0,G$3-1,n,1)),"") | H14: =IF(AND($B14<>"",H$4<>""),CORREL(OFFSET(X,0,$A14-1,n,1),OFFSET(X,0,H$3-1,n,1)),"") | I14: =IF(AND($B14<>"",I$4<>""),CORREL(OFFSET(X,0,$A14-1,n,1),OFFSET(X,0,I$3-1,n,1)),"") | J14: =IF(AND($B14<>"",J$4<>""),CORREL(OFFSET(X,0,$A14-1,n,1),OFFSET(X,0,J$3-1,n,1)),"") | K14: =IF(AND($B14<>"",K$4<>""),CORREL(OFFSET(X,0,$A14-1,n,1),OFFSET(X,0,K$3-1,n,1)),"") | L14: =IF($B14<>"",1,"")
A16: Y | B16: =Data!B4 -> Price | C16: =IF(C4<>"",CORREL(Y,OFFSET(X,0,C3-1,n,1)),"") -> -0.65690997 | D16: =IF(D4<>"",CORREL(Y,OFFSET(X,0,D3-1,n,1)),"") -> -0.039675063 | E16: =IF(E4<>"",CORREL(Y,OFFSET(X,0,E3-1,n,1)),"") -> -0.61785959 | F16: =IF(F4<>"",CORREL(Y,OFFSET(X,0,F3-1,n,1)),"") -> 0.4735268 | G16: =IF(G4<>"",CORREL(Y,OFFSET(X,0,G3-1,n,1)),"") -> 0.11074565 | H16: =IF(H4<>"",CORREL(Y,OFFSET(X,0,H3-1,n,1)),"") -> 0.085755992 | I16: =IF(I4<>"",CORREL(Y,OFFSET(X,0,I3-1,n,1)),"") | J16: =IF(J4<>"",CORREL(Y,OFFSET(X,0,J3-1,n,1)),"") | ... L16: =IF(L4<>"",CORREL(Y,OFFSET(X,0,L3-1,n,1)),"")

Sheet Partial F
A1: Partial F Calculations | C1: =Data!F1 -> Exports
C3: #Independent variables in full model | D3: =k -> 6 | E3: k
C4: #Independent variables dropped from the model | D4: 2 | E4: r | G4: Press the F9 key after entering r.
B6: SSEF | C6: =Results!C15 -> 9.6237899e+08
B7: SSER | C7: =IF(OR(D4=0,D4>=k),"",INDEX(LINEST(Y,XR,TRUE,TRUE),5,2)) -> 9.8680246e+08
B9: Partial F | C9: =IF(C7="","",(C7-C6)/D4/(C6/(n-k-1))) -> 2.4363093
B10: p-value | C10: {=IF(C9="","",FDIST(C9,k-D4,n-k-1))} -> 0.048626074
